Workbook

Sheet Hướng dẫn
A1: Đối soát danh mục bài toán chuẩn (Bước 0)
A2: Mục đích: rà soát dữ liệu trước khi đưa vào app. App chưa thay đổi gì.
A3: Nguồn: bảng 62 bài toán chuẩn kèm 70 bài toán đơn vị và bảng 14 bài ưu tiên, do bạn gửi ngày 14/10/2026.
A5: Cách dùng file
A6: • Chỉ cần điền cột 'Quyết định của bạn' (nền vàng đậm) ở sheet 'Cần quyết định'. Ví dụ: 'Đồng ý' hoặc 'Giữ đầu mối Tập đoàn cho #3'.
A7: • Sheet 'Bài toán chuẩn': ô nền vàng nhạt là chỗ hai nguồn lệch nhau hoặc dữ liệu có vấn đề. Giá trị trong ô là đề xuất; cột 'Ghi chú đối soát' ghi giá trị còn lại.
A8: • Sheet 'Chương trình' và cột 'Số bài toán đơn vị' là công thức, tự cập nhật khi bạn sửa dữ liệu.
A10: Quy tắc đã áp dụng
A11: • Tên 7 chương trình: theo danh sách bạn gửi lúc đầu.
A12: • Tên bài #1 và #46: theo bảng 14 (bạn đã chốt).
A13: • Ưu tiên: đúng 14 bài trong bảng 14.
A14: • Với 14 bài ưu tiên: mức dẫn dắt, đầu mối, đơn vị tiềm năng và năm lấy theo bảng 14.
... A17: • Bài toán đơn vị: giữ tên đang có trong app; tên khai báo ở đây dùng để khớp khi chuyển dữ liệu.

Sheet Cần quyết định
A1: # | B1: Mã bài toán | C1: Vấn đề | D1: Đề xuất (đã áp dụng sẵn trong file) | E1: Quyết định của bạn
A2: 1 | B2: 2, 32 | C2: Bảng 62 ghi 'Ưu tiên triển khai' cho #2 'Tự động tổng hợp báo cáo và quản trị dữ liệu' và #32 'AI cho kinh doanh và khách hàng', nhưng hai bài này không thuộc 14 bài ưu tiên. | D2: Để Không ưu tiên; vẫn giữ năm, đầu mối, đơn vị theo bảng 62 để tham khảo. | E2: Không ưu tiên, lấy theo 14 bài toán thôi
A3: 2 | B3: 3, 5, 8, 31, 51, 55, 59, 61 | C3: Đầu mối ưu tiên khác nhau giữa bảng 62 và bảng 14 (chi tiết ở cột Ghi chú đối soát). | D3: Lấy theo bảng 14. | E3: Lấy theo bảng 14.
A4: 3 | B4: 3, 8, 31, 51, 55, 59 | C4: Đơn vị tiềm năng khác nhau giữa hai bảng. | D4: Lấy theo bảng 14. | E4: Lấy theo bảng 14.
A5: 4 | B5: 17 | C5: Bảng 62 chưa có năm, đầu mối và đơn vị tiềm năng. | D5: Lấy theo bảng 14: năm 2027, đầu mối PVU, đơn vị PV GAS. | E5: Lấy theo bảng 14: năm 2027, đầu mối PVU, đơn vị PV GAS.
A6: 5 | B6: Tất cả | C6: Nhóm bài toán ở bảng 14 khác bảng 62 (bảng 14 dùng các gạch đầu dòng mô tả chương trình). | D6: Dùng nhóm của bảng 62 cho cả 62 bài để thống nhất. | E6: ưu tiên lấy theo bảng 14, cái nào không có thì mới lấy bảng 62
A7: 6 | B7: 14, 49 | C7: Hai bài khác chương trình, khác mô tả nhưng trùng tên 'Quản lý năng lượng, phát thải và carbon/ESG'. | D7: Đổi tên để phân biệt, ví dụ #14 'AI quản lý năng lượng và phát thải nhà máy', #49 'AI quản lý phát thải, carbon và ESG'. Lưu ý #14 khá gần #16. | E7: Ưu tiên bảng 14
A8: 7 | B8: 50, 54 | C8: Trùng tên 'AI cho hợp đồng, đấu thầu và kiểm toán'; mô tả #54 đang là mô tả của bài tài chính #52. | D8: Gộp #50 vào #54: giữ nhóm 'Quản lý hợp đồng, đấu thầu và kiểm toán', dùng mô tả của #50. Danh mục còn 61 bài. | E8: Gộp #50 vào #54: giữ nhóm 'Quản lý hợp đồng, đấu thầu và kiểm toán', dùng mô tả của #50. Danh mục còn 61 bài.
A9: 8 | B9: 34 | C9: Mô tả bị cắt: '…thành file báo cáo Lãnh đạo Tập đoà'. | D9: Sửa thành '…thành file báo cáo Lãnh đạo Tập đoàn.' | E9: Sửa thành '…thành file báo cáo Lãnh đạo Tập đoàn.'
A10: 9 | B10: 51, 55, 59 | C10: Đơn vị tiềm năng ghi 'Toàn bộ các đơn vị trong Tập đoàn'. | D10: Lưu thành cờ 'Toàn Tập đoàn', không gắn từng đơn vị. | E10: Nên gán cho đơn vị để nhìn được bài ưu tiên tiềm năng
A11: 10 | B11: 61 | C11: Đầu mối 'PVU/VPI' gồm hai đơn vị. | D11: Cho phép bài toán chuẩn có 2 đầu mối. | E11: Không, cho 1 thôi, để VPI nhé
A12: 11 | B12: 46, 59, 61 | C12: Một số bài toán đơn vị có vẻ chưa khớp bài chuẩn: PVI 'giám sát hạ tầng - an ninh mạng' → #46 Camera AI; PVE 'AI lập trình và bảo trì hệ thống văn phòng số' → #59; PVU 'nhận thức của sinh viên học tiếng Anh…' → #61. | D12: Giữ như bảng của bạn; chỉ đổi nếu bạn chỉ định bài chuẩn khác. | E12: Giữ như bảng của bạn; chỉ đổi nếu bạn chỉ định bài chuẩn khác.
A13: 12 | B13: 46 | C13: Cột Hiện trạng (bảng 14) ghi PVCFC đã POC camera AI, nhưng bảng 62 không có bài toán của PVCFC gắn #46. | D13: Không tự thêm. Báo nếu cần bổ sung hồ sơ. | E13: Ưu tiên bảng 14
A14: 13 | B14: Tất cả | C14: Bảng có 70 bài toán đơn vị; app hiện có 69 bài toán + 70 nhu cầu từ khảo sát. | D14: Khi chuyển dữ liệu: khớp theo đơn vị + tên khai báo, giữ tên đang có trong app, báo lại dòng không khớp. | E14: Khi chuyển dữ liệu: khớp theo đơn vị + tên khai báo, giữ tên đang có trong app, báo lại dòng không khớp.

Sheet Chương trình
A1: STT | B1: Chương trình AI | C1: Số bài toán chuẩn | D1: Số bài ưu tiên | E1: Số bài toán đơn vị
A2: 1 | B2: 1. AI cho tìm kiếm, thăm dò và khai thác | C2: =COUNTIF('Bài toán chuẩn'!$B:$B,B2) -> 13 | D2: =COUNTIFS('Bài toán chuẩn'!$B:$B,B2,'Bài toán chuẩn'!$E:$E,"Có") -> 4 | E2: =COUNTIF('Bài toán đơn vị'!$C:$C,B2) -> 10
A3: 2 | B3: 2. AI cho vận hành, hiệu suất, độ tin cậy và toàn vẹn tài sản | C3: =COUNTIF('Bài toán chuẩn'!$B:$B,B3) -> 12 | D3: =COUNTIFS('Bài toán chuẩn'!$B:$B,B3,'Bài toán chuẩn'!$E:$E,"Có") -> 3 | E3: =COUNTIF('Bài toán đơn vị'!$C:$C,B3) -> 11
A4: 3 | B4: 3. AI cho hoạch định, thương mại và tối ưu chuỗi năng lượng | C4: =COUNTIF('Bài toán chuẩn'!$B:$B,B4) -> 15 | D4: =COUNTIFS('Bài toán chuẩn'!$B:$B,B4,'Bài toán chuẩn'!$E:$E,"Có") -> 1 | E4: =COUNTIF('Bài toán đơn vị'!$C:$C,B4) -> 9
A5: 4 | B5: 4. AI cho dự án đầu tư, EPCI và quản lý dự án | C5: =COUNTIF('Bài toán chuẩn'!$B:$B,B5) -> 4 | D5: =COUNTIFS('Bài toán chuẩn'!$B:$B,B5,'Bài toán chuẩn'!$E:$E,"Có") -> 1 | E5: =COUNTIF('Bài toán đơn vị'!$C:$C,B5) -> 2
A6: 5 | B6: 5. AI cho an toàn, môi trường, rủi ro và kiểm soát tuân thủ | C6: =COUNTIF('Bài toán chuẩn'!$B:$B,B6) -> 5 | D6: =COUNTIFS('Bài toán chuẩn'!$B:$B,B6,'Bài toán chuẩn'!$E:$E,"Có") -> 1 | E6: =COUNTIF('Bài toán đơn vị'!$C:$C,B6) -> 5
A7: 6 | B7: 6. AI cho quản trị, điều hành và hiệu quả hoạt động doanh nghiệp | C7: =COUNTIF('Bài toán chuẩn'!$B:$B,B7) -> 11 | D7: =COUNTIFS('Bài toán chuẩn'!$B:$B,B7,'Bài toán chuẩn'!$E:$E,"Có") -> 3 | E7: =COUNTIF('Bài toán đơn vị'!$C:$C,B7) -> 29
A8: 7 | B8: 7. AI cho nghiên cứu, đổi mới sáng tạo và sản phẩm, công nghệ | C8: =COUNTIF('Bài toán chuẩn'!$B:$B,B8) -> 2 | D8: =COUNTIFS('Bài toán chuẩn'!$B:$B,B8,'Bài toán chuẩn'!$E:$E,"Có") -> 1 | E8: =COUNTIF('Bài toán đơn vị'!$C:$C,B8) -> 4
B9: Tổng | C9: =SUM(C2:C8) -> 62 | D9: =SUM(D2:D8) -> 14 | E9: =SUM(E2:E8) -> 70

Sheet Bài toán chuẩn
A1: Mã | B1: Chương trình | C1: Nhóm bài toán | D1: Tên bài toán chuẩn | E1: Ưu tiên | F1: Mức dẫn dắt | G1: Đầu mối ưu tiên | H1: Đơn vị tiềm năng | I1: Năm dự kiến | J1: Số bài toán đơn vị | K1: Mô tả | L1: Ghi chú đối soát
A2: 1 | B2: 1. AI cho tìm kiếm, thăm dò và khai thác | C2: Cơ sở dữ liệu và tra cứu/tìm kiếm | D2: AI tìm kiếm và tra cứu tri thức nội bộ chuyên ngành thăm dò - khai thác | E2: Có | F2: Tập đoàn triển khai | G2: Tập đoàn | H2: PVEP; VSP; BIENDONG POC; PQPOC; VPI | I2: 2026 | J2: =COUNTIF('Bài toán đơn vị'!$A:$A,A2) -> 1 | K2: Ứng dụng AI hỗ trợ tìm kiếm, tra cứu, hỏi – đáp và tổng hợp dữ liệu, tài liệu và tri thức nội bộ/chuyên ngành E&P từ các cơ sở dữ liệu và tài liệu chuyên môn; cung cấp kết quả kèm nguồn tham chiếu phục vụ nghiên cứu và tác nghiệp chuyên môn. | L2: Tên theo bảng 14 (bạn đã chốt). Bảng 62: AI tìm kiếm và tra cứu tri thức nội bộ, chuyên ngành
A3: 2 | B3: 1. AI cho tìm kiếm, thăm dò và khai thác | C3: Cơ sở dữ liệu và tra cứu/tìm kiếm | D3: Tự động tổng hợp báo cáo và quản trị dữ liệu | E3: Không | G3: Tập đoàn | H3: PVEP; VSP; BIENDONG POC; PQPOC; VPI | I3: 2026 | J3: =COUNTIF('Bài toán đơn vị'!$A:$A,A3) -> 0 | K3: Ứng dụng AI hỗ trợ thu thập, tổng hợp và chuẩn hóa dữ liệu từ các nguồn E&P; tự động tổng hợp báo cáo định kỳ, báo cáo quản trị và hỗ trợ tra cứu, theo dõi dữ liệu phục vụ công tác điều hành. | L3: Bảng 62 ghi 'Ưu tiên triển khai' nhưng không thuộc 14 bài ưu tiên
A4: 3 | B4: 1. AI cho tìm kiếm, thăm dò và khai thác | C4: Hiệu chỉnh, xử lý, minh giải, tổng hợp và phân tích tài liệu giếng khoan | D4: Hiệu chỉnh và chuẩn hóa dữ liệu giếng khoan | E4: Có | F4: Tập đoàn dẫn dắt, đơn vị triển khai | G4: VPI | H4: PVEP; VSP; BIENDONG POC; PQPOC | I4: 2027 | J4: =COUNTIF('Bài toán đơn vị'!$A:$A,A4) -> 1 | K4: Ứng dụng AI/ML hỗ trợ kiểm tra chất lượng, phát hiện dữ liệu thiếu/bất thường và hiệu chỉnh, chuẩn hóa dữ liệu giếng khoan, bao gồm hỗ trợ dự báo missing log, phục vụ các bước xử lý và minh giải tiếp theo. | L4: Đầu mối bảng 62: Tập đoàn Đơn vị khác bảng 62: PVEP; VSP; BIENDONG POC; PQPOC; VPI
A5: 4 | B5: 1. AI cho tìm kiếm, thăm dò và khai thác | C5: Hiệu chỉnh, xử lý, minh giải, tổng hợp và phân tích tài liệu giếng khoan | D5: Xử lý và minh giải tài liệu giếng khoan | E5: Không | J5: =COUNTIF('Bài toán đơn vị'!$A:$A,A5) -> 0 | K5: Ứng dụng AI/ML hỗ trợ xử lý, phân tích và minh giải dữ liệu giếng khoan/well-log, nhận diện các đặc trưng địa chất – địa vật lý và hỗ trợ chuyên gia đánh giá tầng chứa.
A6: 5 | B6: 1. AI cho tìm kiếm, thăm dò và khai thác | C6: Hiệu chỉnh, xử lý, minh giải, tổng hợp và phân tích tài liệu giếng khoan | D6: Phân tích, đánh giá và tổng hợp kết quả giếng khoan | E6: Có | F6: Tập đoàn dẫn dắt, đơn vị triển khai | G6: PVEP | H6: PVEP; VSP; BIENDONG POC; PQPOC; VPI | I6: 2027 | J6: =COUNTIF('Bài toán đơn vị'!$A:$A,A6) -> 2 | K6: Ứng dụng AI hỗ trợ tổng hợp kết quả giếng khoan từ các nguồn dữ liệu liên quan, phân tích và so sánh các chỉ tiêu chính, hỗ trợ đánh giá kết quả giếng và phục vụ cập nhật nhận định địa chất, khai thác. | L6: Đầu mối bảng 62: Tập đoàn
A7: 6 | B7: 1. AI cho tìm kiếm, thăm dò và khai thác | C7: Minh giải và tổng hợp tài liệu địa chấn | D7: Ứng dụng AI hỗ trợ minh giải cấu trúc địa chất | E7: Không | J7: =COUNTIF('Bài toán đơn vị'!$A:$A,A7) -> 1 | K7: Ứng dụng AI/ML hỗ trợ nhận diện và minh giải các cấu trúc địa chất trên tài liệu địa chấn, hỗ trợ xây dựng bản đồ địa chấn và rút ngắn thời gian xử lý, minh giải.
A8: 7 | B8: 1. AI cho tìm kiếm, thăm dò và khai thác | C8: Minh giải và tổng hợp tài liệu địa chấn | D8: AI hỗ trợ minh giải thuộc tính địa chấn đặc biệt | E8: Không | J8: =COUNTIF('Bài toán đơn vị'!$A:$A,A8) -> 1 | K8: Ứng dụng AI/ML, bao gồm CNN, hỗ trợ phân tích và minh giải các thuộc tính địa chấn, nghịch đảo địa chấn và dự báo phân bố, thuộc tính đá chứa phục vụ đánh giá tầng chứa.
A9: 8 | B9: 1. AI cho tìm kiếm, thăm dò và khai thác | C9: Minh giải và tổng hợp tài liệu địa chấn | D9: AI phân tích tổng hợp tài liệu địa chất, địa chấn để đánh giá tiềm năng dầu khí | E9: Có | F9: Tập đoàn dẫn dắt, đơn vị triển khai | G9: VSP | H9: PVEP; BIENDONG POC; PQPOC; VPI | I9: 2027 | J9: =COUNTIF('Bài toán đơn vị'!$A:$A,A9) -> 1 | K9: Ứng dụng AI hỗ trợ tổng hợp và phân tích dữ liệu địa chất, địa chấn, giếng khoan và các thuộc tính liên quan để đánh giá tiềm năng dầu khí, hỗ trợ nhận diện và xếp hạng các khu vực triển vọng. | L9: Đầu mối bảng 62: Tập đoàn Đơn vị khác bảng 62: PVEP; VSP; BIENDONG POC; PQPOC; VPI
A10: 9 | B10: 1. AI cho tìm kiếm, thăm dò và khai thác | C10: Minh giải và tổng hợp tài liệu địa chấn | D10: Ứng dụng AI hỗ trợ lựa chọn các vị trí khoan thăm dò khai thác theo phương án địa chất | E10: Không | J10: =COUNTIF('Bài toán đơn vị'!$A:$A,A10) -> 0 | K10: Ứng dụng AI hỗ trợ tổng hợp các kết quả địa chất, địa chấn và mô hình hiện có để so sánh, đánh giá và hỗ trợ lựa chọn các vị trí khoan thăm dò, khai thác theo phương án địa chất.
A11: 10 | B11: 1. AI cho tìm kiếm, thăm dò và khai thác | C11: Quản trị tài chính, hợp đồng và PSC dầu khí | D11: Trợ lý AI tự động hóa quản lý doanh thu, chi phí, phân chia sản phẩm dầu/khí | E11: Không | J11: =COUNTIF('Bài toán đơn vị'!$A:$A,A11) -> 1 | K11: AI kết nối dữ liệu ERP và các báo cáo sản lượng khai thác, báo cáo thu hồi chi phí, báo cáo chi phí, quy định của PSC, quy định về thuế để phân chia sản phẩm dầu khí, xác định thu hồi chi phí và nghĩa vụ thuế. • Có cảnh báo đến hạn mức THCP
A12: 11 | B12: 1. AI cho tìm kiếm, thăm dò và khai thác | C12: Quản trị tài chính, hợp đồng và PSC dầu khí | D12: Trợ lý AI quản trị, hỏi đáp, kiểm toán và rủi ro hợp đồng dầu khí | E12: Không | J12: =COUNTIF('Bài toán đơn vị'!$A:$A,A12) -> 1 | K12: Ứng dụng AI (LLM kết hợp RAG) để: • tra cứu điều khoản PSC • đối chiếu quy định pháp luật • rà soát hồ sơ chi phí • phát hiện khoản chi chưa phù hợp hợp đồng • phát hiện sai lệch giữa hồ sơ thanh toán và chứng từ • tổng hợp bằng chứng kiểm toán • hỗ trợ lập giấy tờ làm việc • hỗ trợ soạn báo cáo kiểm toán Trợ lý hỏi đáp hợp đồng dầu khí Kiểm toán chi phí thu hồi hợp đồng dầu khí
A13: 12 | B13: 1. AI cho tìm kiếm, thăm dò và khai thác | C13: Thẩm định phát triển mỏ dầu khí | D13: Trợ lý AI phân tích kinh tế mỏ cận biên và gia hạn PSC | E13: Không | J13: =COUNTIF('Bài toán đơn vị'!$A:$A,A13) -> 0 | K13: Trợ lý kinh tế mỏ cận biên và gia hạn PSC
A14: 13 | B14: 1. AI cho tìm kiếm, thăm dò và khai thác | C14: Tự động hóa xây dựng mô hình tĩnh động và tối ưu phương án khai thác | D14: Ứng dụng AI đưa ra các phương án khai thác phù hợp dựa trên mô hình hiện hữu | E14: Không | J14: =COUNTIF('Bài toán đơn vị'!$A:$A,A14) -> 1 | K14: Ứng dụng AI/ML khai thác các mô hình tĩnh, động và dữ liệu khai thác hiện hữu để phân tích, so sánh và đề xuất các phương án khai thác phù hợp; hỗ trợ đánh giá phương án nâng cao sản lượng và hệ số thu hồi dầu khí.
A15: 14 | B15: 2. AI cho vận hành, hiệu suất, độ tin cậy và toàn vẹn tài sản | C15: Giám sát, dự báo và tối ưu vận hành nhà máy | D15: Quản lý năng lượng, phát thải và carbon/ESG | E15: Không | J15: =COUNTIF('Bài toán đơn vị'!$A:$A,A15) -> 0 | K15: Ứng dụng AI phân tích dữ liệu vận hành từ DCS, SCADA, Historian và các hệ thống liên quan để đánh giá hiệu quả sử dụng năng lượng, nhận diện các điểm tiêu hao bất thường và hỗ trợ đề xuất chế độ vận hành tối ưu nhằm giảm tiêu hao năng lượng và phát thải của nhà máy. | L15: Trùng tên với #49
A16: 15 | B16: 2. AI cho vận hành, hiệu suất, độ tin cậy và toàn vẹn tài sản | C16: Giám sát, dự báo và tối ưu vận hành nhà máy | D16: AI hỗ trợ tối ưu chế độ vận hành lò hơi thông qua điều chỉnh Oxy dư | E16: Không | J16: =COUNTIF('Bài toán đơn vị'!$A:$A,A16) -> 1 | K16: Ứng dụng AI phân tích các thông số vận hành, hiệu suất lò hơi trong quá khứ và dữ liệu thời gian thực để tính toán, đề xuất mức thiết lập Oxy dư phù hợp, qua đó hỗ trợ tối ưu hiệu suất vận hành lò hơi của nhà máy nhiệt điện than.
A17: 16 | B17: 2. AI cho vận hành, hiệu suất, độ tin cậy và toàn vẹn tài sản | C17: Giám sát, dự báo và tối ưu vận hành nhà máy | D17: AI giám sát, tối ưu vận hành, năng lượng và phát thải nhà máy | E17: Có | F17: Tập đoàn dẫn dắt, đơn vị triển khai | G17: PVCFC | H17: PV GAS; BSR; NSRP; PVFCCO; PV Power; PVPGB; VNPOLY | I17: 2027 | J17: =COUNTIF('Bài toán đơn vị'!$A:$A,A17) -> 2 | K17: Ứng dụng AI khai thác dữ liệu từ Data Platform, DCS, SCADA, Historian, CMMS và các thiết bị hiện trường để giám sát trạng thái vận hành, dự báo diễn biến các thông số công nghệ như mức bồn, áp suất, lưu lượng; phát hiện bất thường của quá trình và hỗ trợ điều hành sản xuất. Đồng thời hỗ trợ đánh giá hiệu suất thiết bị, tối ưu tiêu hao năng lượng, phát thải và đưa ra cảnh báo hoặc khuyến nghị vận hành. Nội dung khai báo cũng bao gồm hỗ trợ dự báo nhu cầu bảo dưỡng, sửa chữa và nghiên cứu ứng dụng AI trong rà soát, thẩm định P&ID.
A18: 17 | B18: 2. AI cho vận hành, hiệu suất, độ tin cậy và toàn vẹn tài sản | C18: Giám sát, kiểm tra và đánh giá toàn vẹn đường ống | D18: AI phân tích dữ liệu PIG/MFL để nhận diện khuyết tật đường ống | E18: Có | F18: Tập đoàn dẫn dắt, đơn vị triển khai | G18: PVU | H18: PV GAS | I18: 2027 | J18: =COUNTIF('Bài toán đơn vị'!$A:$A,A18) -> 1 | K18: Nghiên cứu ứng dụng thuật toán AI kết hợp dữ liệu rò rỉ đường sức từ MFL thu thập từ thiết bị khảo sát đường ống PIG để xử lý tín hiệu, nhận diện, phân loại và xác định kích thước các khuyết tật trên đường ống thép; qua đó nâng cao độ chính xác và mức độ tự động hóa trong công tác khảo sát, kiểm tra và đánh giá tình trạng đường ống. | L18: Bảng 62 để trống năm, đầu mối, đơn vị: lấy theo bảng 14
A19: 18 | B19: 2. AI cho vận hành, hiệu suất, độ tin cậy và toàn vẹn tài sản | C19: Giám sát, kiểm tra và đánh giá toàn vẹn đường ống | D19: AI và cảm biến giám sát rò rỉ, xâm nhập và ăn mòn đường ống | E19: Không | J19: =COUNTIF('Bài toán đơn vị'!$A:$A,A19) -> 0 | K19: Ứng dụng AI kết hợp dữ liệu thu thập từ các hệ thống cảm biến để giám sát tình trạng đường ống, nhận diện và cảnh báo các dấu hiệu rò rỉ, xâm nhập, ăn mòn hoặc các trạng thái bất thường, phục vụ công tác giám sát an toàn và quản lý toàn vẹn hệ thống đường ống.
A20: 19 | B20: 2. AI cho vận hành, hiệu suất, độ tin cậy và toàn vẹn tài sản | C20: Lập kế hoạch và điều phối bảo dưỡng lớn | D20: Điều phối lịch bảo dưỡng lớn | E20: Không | J20: =COUNTIF('Bài toán đơn vị'!$A:$A,A20) -> 0 | K20: Xây dựng công cụ hỗ trợ điều phối lịch bảo dưỡng lớn giữa các nhà máy, công trình và đơn vị liên quan trên cơ sở kế hoạch sản xuất, tình trạng thiết bị, chu kỳ bảo dưỡng, nguồn lực nhân sự, vật tư, nhà thầu và thời gian dừng máy. Ứng dụng AI và thuật toán tối ưu để phát hiện xung đột lịch, đánh giá tác động của từng phương án đến sản lượng, chuỗi cung ứng và nghĩa vụ giao hàng, đồng thời đề xuất thời điểm và trình tự bảo dưỡng phù hợp. Giải pháp cho phép mô phỏng thay đổi tiến độ, sự cố phát sinh hoặc thiếu nguồn lực; hỗ trợ theo dõi các mốc công việc, đường găng và cảnh báo nguy cơ chậm tiến độ.
A21: 20 | B21: 2. AI cho vận hành, hiệu suất, độ tin cậy và toàn vẹn tài sản | C21: Mô phỏng và tối ưu vận hành bằng Digital Twin | D21: Digital Twin nhà máy điện và tối ưu vận hành chuỗi khí – điện | E21: Không | J21: =COUNTIF('Bài toán đơn vị'!$A:$A,A21) -> 1 | K21: Xây dựng nền tảng dữ liệu công nghiệp và mô hình Digital Twin nhằm hỗ trợ giám sát, mô phỏng và tối ưu vận hành nhà máy điện; từng bước mở rộng sang Digital Twin và tối ưu vận hành liên đơn vị trong chuỗi khí – điện.
A22: 21 | B22: 2. AI cho vận hành, hiệu suất, độ tin cậy và toàn vẹn tài sản | C22: Mô phỏng và tối ưu vận hành bằng Digital Twin | D22: Digital Twin và AI/ML tối ưu vận hành nhà máy lọc hóa dầu | E22: Không | J22: =COUNTIF('Bài toán đơn vị'!$A:$A,A22) -> 0 | K22: Nghiên cứu ứng dụng AI/ML kết hợp các hệ thống APC/RTO và Digital Twin nhằm hỗ trợ giám sát, mô phỏng và tối ưu các quá trình công nghệ trong nhà máy lọc hóa dầu. Digital Twin được xây dựng trên cơ sở tích hợp dữ liệu vận hành và các mô hình công nghệ để phản ánh trạng thái nhà máy, hỗ trợ phân tích các kịch bản và nâng cao hiệu quả tối ưu vận hành.
A23: 22 | B23: 2. AI cho vận hành, hiệu suất, độ tin cậy và toàn vẹn tài sản | C23: Mô phỏng và tối ưu vận hành bằng Digital Twin | D23: Digital Twin và tối ưu vận hành hệ thống đường ống khí | E23: Không | J23: =COUNTIF('Bài toán đơn vị'!$A:$A,A23) -> 0 | K23: Xây dựng Digital Twin cho hệ thống đường ống khí trên cơ sở tích hợp dữ liệu vận hành thực tế để hỗ trợ giám sát trạng thái hệ thống, mô phỏng các chế độ và kịch bản vận hành, đồng thời hỗ trợ phân tích và tối ưu vận hành hệ thống đường ống khí.
A24: 23 | B24: 2. AI cho vận hành, hiệu suất, độ tin cậy và toàn vẹn tài sản | C24: Quản lý tài sản, giám sát tình trạng và bảo trì dự báo | D24: AI hỗ trợ chẩn đoán và dự báo hỏng hóc thiết bị quay nhà máy điện | E24: Có | F24: Tập đoàn dẫn dắt, đơn vị triển khai | G24: PV Power | H24: PVPGB; BSR; NSRP; PVCFC; PVFCCO | I24: 2026 | J24: =COUNTIF('Bài toán đơn vị'!$A:$A,A24) -> 2 | K24: Thu thập dữ liệu vận hành thời gian thực như dòng điện, độ rung, nhiệt độ, từ thông của các thiết bị quay chính trong nhà máy điện như ID Fan, FD Fan, bơm… để AI phân tích tình trạng, phát hiện bất thường và dự báo nguy cơ hoặc thời gian đến hỏng hóc, qua đó hỗ trợ xây dựng kế hoạch bảo trì, sửa chữa phù hợp.
A25: 24 | B25: 2. AI cho vận hành, hiệu suất, độ tin cậy và toàn vẹn tài sản | C25: Quản lý tài sản, giám sát tình trạng và bảo trì dự báo | D25: AI quản lý tài sản, phát hiện bất thường và bảo trì tiên đoán thiết bị công nghiệp | E25: Không | J25: =COUNTIF('Bài toán đơn vị'!$A:$A,A25) -> 3 | K25: Ứng dụng AI hỗ trợ quản lý tài sản, thiết bị theo vòng đời; phân loại, gắn mã, theo dõi biến động, kiểm kê, khấu hao và nhu cầu sử dụng/trang bị. Đồng thời phân tích dữ liệu cảm biến, dữ liệu vận hành và lịch sử hỏng hóc, bảo trì, bảo dưỡng để phát hiện sớm bất thường, phân tích nguyên nhân, dự báo nguy cơ hư hỏng và hỗ trợ tối ưu kế hoạch bảo trì. Phạm vi áp dụng gồm các thiết bị quan trọng tại nhà máy lọc hóa dầu, Gas Compressor, máy nén, máy bơm và các thiết bị công nghiệp khí.
A26: 25 | B26: 2. AI cho vận hành, hiệu suất, độ tin cậy và toàn vẹn tài sản | C26: Tra cứu, hỏi đáp và khai thác tri thức vận hành nhà máy | D26: Trợ lý AI hỏi đáp kiến thức vận hành nhà máy | E26: Không | J26: =COUNTIF('Bài toán đơn vị'!$A:$A,A26) -> 1 | K26: Xây dựng trợ lý AI/Chatbot hỗ trợ tra cứu và hỏi đáp các thông tin, tài liệu và kiến thức liên quan đến vận hành nhà máy, giúp người dùng tiếp cận nhanh các nội dung chuyên môn phục vụ công tác vận hành.
A27: 26 | B27: 3. AI cho hoạch định, thương mại và tối ưu chuỗi năng lượng | C27: Dự báo, cân đối và điều độ khí/LNG | D27: AI dự báo và cân đối cung – cầu khí/LNG | E27: Không | J27: =COUNTIF('Bài toán đơn vị'!$A:$A,A27) -> 0 | K27: Ứng dụng AI để tổng hợp và phân tích dữ liệu cung, nhu cầu tiêu thụ và các yếu tố liên quan nhằm dự báo, cân đối cung – cầu khí/LNG theo từng giai đoạn; hỗ trợ đánh giá tình trạng thiếu/thừa nguồn và cung cấp thông tin phục vụ công tác lập kế hoạch, điều hành và quyết định thương mại.
A28: 27 | B28: 3. AI cho hoạch định, thương mại và tối ưu chuỗi năng lượng | C28: Dự báo, cân đối và điều độ khí/LNG | D28: AI tối ưu điều độ LNG, nhập khẩu và tồn kho | E28: Không | J28: =COUNTIF('Bài toán đơn vị'!$A:$A,A28) -> 0 | K28: Ứng dụng AI hỗ trợ dự báo nhu cầu, cân đối nguồn cung và tối ưu kế hoạch nhập khẩu, điều độ tiếp nhận LNG và quản lý mức tồn kho, phục vụ nâng cao hiệu quả vận hành và điều hành chuỗi cung ứng LNG.
A29: 28 | B29: 3. AI cho hoạch định, thương mại và tối ưu chuỗi năng lượng | C29: Dự báo, cân đối và điều độ khí/LNG | D29: Cân đối/điều độ khí - LNG | E29: Không | J29: =COUNTIF('Bài toán đơn vị'!$A:$A,A29) -> 0 | K29: Ứng dụng AI và mô hình tối ưu để tổng hợp nhu cầu khí, khả năng cung cấp từ các nguồn trong nước, kế hoạch nhập LNG, năng lực kho cảng, tồn chứa, tái hóa khí và giới hạn vận chuyển của hệ thống đường ống. Giải pháp hỗ trợ lập và cập nhật phương án cân đối nguồn – nhu cầu theo ngày, tháng và kỳ kế hoạch; tối ưu lịch tiếp nhận tàu, phân bổ khí/LNG cho từng khách hàng và xử lý các ràng buộc vận hành, hợp đồng, chất lượng khí và mức tồn kho an toàn. Hệ thống mô phỏng các tình huống thiếu nguồn, chậm tàu, biến động nhu cầu hoặc sự cố hạ tầng, từ đó đề xuất phương án điều độ khả thi và cảnh báo sớm nguy cơ mất cân đối.
A30: 29 | B30: 3. AI cho hoạch định, thương mại và tối ưu chuỗi năng lượng | C30: Giám sát hiệu quả sản xuất – kinh doanh, công suất và tồn kho | D30: AI giám sát biên lợi nhuận, công suất và tồn kho lọc hóa dầu | E30: Không | J30: =COUNTIF('Bài toán đơn vị'!$A:$A,A30) -> 0 | K30: Ứng dụng AI hỗ trợ tổng hợp, theo dõi và phân tích các chỉ tiêu biên lợi nhuận/crack margin, công suất sản xuất và mức tồn kho trong hoạt động lọc hóa dầu, phục vụ công tác giám sát hiệu quả sản xuất – kinh doanh và hỗ trợ điều hành.
A31: 30 | B31: 3. AI cho hoạch định, thương mại và tối ưu chuỗi năng lượng | C31: Mô phỏng, cân đối và tối ưu nguyên liệu – sản xuất – tồn kho | D31: Mô phỏng kịch bản cân đối nguyên liệu - sản xuất - tồn kho | E31: Không | J31: =COUNTIF('Bài toán đơn vị'!$A:$A,A31) -> 0 | K31: Xây dựng mô hình mô phỏng và tối ưu tích hợp chuỗi nguyên liệu – sản xuất – tồn kho trên cơ sở nhu cầu thị trường, hợp đồng mua bán, năng lực thiết bị, định mức tiêu hao, kế hoạch nhập nguyên liệu, cơ cấu sản phẩm và giới hạn kho chứa. Giải pháp cho phép thiết lập, so sánh các kịch bản về giá, nhu cầu, nguồn cung, công suất, dừng máy và chính sách tồn kho; lượng hóa tác động đến sản lượng, chi phí, biên lợi nhuận, mức tồn kho và khả năng đáp ứng đơn hàng. Kết quả hỗ trợ lựa chọn phương án vận hành và kế hoạch mua – sản xuất – bán tối ưu, đồng thời cảnh báo nguy cơ thiếu nguyên liệu, quá tải kho hoặc mất cân đối sản phẩm.
A32: 31 | B32: 3. AI cho hoạch định, thương mại và tối ưu chuỗi năng lượng | C32: Nhận dạng, tra cứu và chuẩn hóa vật tư kỹ thuật | D32: AI nhận dạng, tra cứu và đối chiếu vật tư kỹ thuật | E32: Có | F32: Tập đoàn dẫn dắt, đơn vị triển khai | G32: PV Power | H32: NSRP; PVPGB; BSR; PV GAS; PVCFC; PVFCCO; PTSC; PVMR; PV Drilling | I32: 2027 | J32: =COUNTIF('Bài toán đơn vị'!$A:$A,A32) -> 2 | K32: Ứng dụng AI tích hợp với hệ thống quản lý danh điểm vật tư để hỗ trợ tìm kiếm, chuẩn hóa dữ liệu vật tư và xác định vật tư tương đương dựa trên hình ảnh hoặc thông số kỹ thuật. Giải pháp có thể kết hợp cơ sở dữ liệu vật tư và hình ảnh, cơ sở dữ liệu vector, AI Engine và Chatbot để hỗ trợ tra cứu nhanh và cung cấp thông tin chi tiết về vật tư. | L32: Đầu mối bảng 62: PVPGB Đơn vị khác bảng 62: NSRP; PV Power; BSR; PV GAS; PVCFC; PVFCCO; PTSC; PVMR; PV Drilling
A33: 32 | B33: 3. AI cho hoạch định, thương mại và tối ưu chuỗi năng lượng | C33: Phân tích kinh doanh, khách hàng và phát triển sản phẩm, dịch vụ | D33: AI cho kinh doanh và khách hàng | E33: Không | G33: PVI | H33: PVcomBank; PVOIL; PVFCCO; PVCFC; PVCHEM; PV GAS | I33: 2026 | J33: =COUNTIF('Bài toán đơn vị'!$A:$A,A33) -> 3 | K33: Hỗ trợ dự báo giá và nhu cầu, phân tích thị trường và kinh doanh, tư vấn hoặc tương tác với khách hàng, người dùng và hỗ trợ phát triển sản phẩm, dịch vụ. | L33: Bảng 62 ghi 'Ưu tiên triển khai' nhưng không thuộc 14 bài ưu tiên
A34: 33 | B34: 3. AI cho hoạch định, thương mại và tối ưu chuỗi năng lượng | C34: Phân tích, dự báo thị trường, giá, nhu cầu và hỗ trợ quyết định thương mại | D34: AI phân tích, dự báo thị trường, giá và hỗ trợ quyết định thương mại | E34: Không | J34: =COUNTIF('Bài toán đơn vị'!$A:$A,A34) -> 1 | K34: Ứng dụng AI/LLM để tự động tổng hợp tin tức, diễn biến thị trường và giá cả, xây dựng bản tin định kỳ và CSDL để dự báo giá, nhu cầu và phân tích các yếu tố ảnh hưởng đến giá bán. Hệ thống hỗ trợ đề xuất khoảng giá hoặc các kịch bản giá theo sản phẩm, thị trường, khu vực, nhóm khách hàng, kênh phân phối và thời điểm; cung cấp phân tích, cảnh báo và khuyến nghị phục vụ người có thẩm quyền xem xét, quyết định. Kết quả AI không tự động ban hành hoặc thay đổi giá bán và không thay thế trách nhiệm thẩm định, phê duyệt của các cấp có thẩm quyền.
A35: 34 | B35: 3. AI cho hoạch định, thương mại và tối ưu chuỗi năng lượng | C35: Phân tích, dự báo thị trường, giá, nhu cầu và hỗ trợ quyết định thương mại | D35: AI tự động hóa báo cáo thị trường và tồn kho hàng ngày | E35: Không | J35: =COUNTIF('Bài toán đơn vị'!$A:$A,A35) -> 1 | K35: Tự động tổng hợp, chuẩn hóa và trình bày báo cáo thị trường dầu thô, xăng dầu, khí, phân bón và tồn kho các đơn vị thành file báo cáo Lãnh đạo Tập đoà | L35: Mô tả bị cắt cụt ở cuối
A36: 35 | B36: 3. AI cho hoạch định, thương mại và tối ưu chuỗi năng lượng | C36: Phân tích, dự báo thị trường, giá, nhu cầu và hỗ trợ quyết định thương mại | D36: AI xây dựng và duy trì CSDL thông tin thị trường tổng hợp. | E36: Không | J36: =COUNTIF('Bài toán đơn vị'!$A:$A,A36) -> 0 | K36: Hỗ trợ thu thập, phân loại và cập nhật dữ liệu thị trường năng lượng từ nhiều nguồn phục vụ tra cứu và phân tích chung của Ban.
A37: 36 | B37: 3. AI cho hoạch định, thương mại và tối ưu chuỗi năng lượng | C37: Phân tích, dự báo thị trường, giá, nhu cầu và hỗ trợ quyết định thương mại | D37: AI dự báo giá và phân tích thị trường phục vụ giao dịch thương mại. | E37: Không | J37: =COUNTIF('Bài toán đơn vị'!$A:$A,A37) -> 1 | K37: Phân tích dữ liệu giá, cung – cầu và các yếu tố vĩ mô để hỗ trợ ra quyết định giao dịch dầu thô, xăng dầu, khí, điện, than.
A38: 37 | B38: 3. AI cho hoạch định, thương mại và tối ưu chuỗi năng lượng | C38: Phân tích, dự báo thị trường, giá, nhu cầu và hỗ trợ quyết định thương mại | D38: Dự báo thị trường dùng chung | E38: Không | J38: =COUNTIF('Bài toán đơn vị'!$A:$A,A38) -> 0 | K38: Xây dựng nền tảng dự báo thị trường dùng chung, tích hợp dữ liệu lịch sử tiêu thụ, giá cả, cung – cầu, tồn kho, hoạt động sản xuất – kinh doanh và các yếu tố kinh tế, mùa vụ có liên quan. Ứng dụng AI/ML để nhận diện xu hướng, dự báo nhu cầu và giá theo từng sản phẩm, khu vực và kỳ kế hoạch; đồng thời cho phép các đơn vị sử dụng chung một bộ giả định, kịch bản và phiên bản dự báo. Kết quả hỗ trợ lập kế hoạch sản xuất, kinh doanh, mua hàng, logistics và ngân sách; cung cấp cảnh báo sớm khi thị trường biến động hoặc kết quả thực tế lệch đáng kể so với dự báo.
A39: 38 | B39: 3. AI cho hoạch định, thương mại và tối ưu chuỗi năng lượng | C39: Quản trị hợp đồng và nghiệp vụ thương mại | D39: Trợ lý AI quản lý, rà soát và hỗ trợ soạn thảo hợp đồng thương mại | E39: Không | J39: =COUNTIF('Bài toán đơn vị'!$A:$A,A39) -> 1 | K39: Xây dựng trợ lý AI hỗ trợ quản lý và khai thác thông tin hợp đồng thương mại; tra cứu, rà soát điều khoản, nghĩa vụ và các nội dung cần lưu ý; đồng thời hỗ trợ soạn thảo, hiệu chỉnh và chuẩn hóa hợp đồng trên cơ sở mẫu biểu, quy định và hồ sơ liên quan.
A40: 39 | B40: 3. AI cho hoạch định, thương mại và tối ưu chuỗi năng lượng | C40: Quản trị hợp đồng và nghiệp vụ thương mại | D40: AI hỗ trợ đàm phán và quản lý vòng đời hợp đồng thương mại quốc tế. | E40: Không | J40: =COUNTIF('Bài toán đơn vị'!$A:$A,A40) -> 0 | K40: Rà soát điều khoản, đối chiếu tiền lệ đàm phán và cảnh báo rủi ro đối với các hợp đồng JMA, LA, GSPA, GTA, PPA.
...

Sheet Bài toán đơn vị
A1: Mã bài toán chuẩn | B1: Tên bài toán chuẩn | C1: Chương trình | D1: Mã đơn vị | E1: Đơn vị | F1: Tên bài toán đơn vị khai báo
A2: 1 | B2: =INDEX('Bài toán chuẩn'!$D:$D,MATCH(A2,'Bài toán chuẩn'!$A:$A,0)) -> AI tìm kiếm và tra cứu tri thức nội bộ chuyên ngành thăm dò - khai thác | C2: =INDEX('Bài toán chuẩn'!$B:$B,MATCH(A2,'Bài toán chuẩn'!$A:$A,0)) -> 1. AI cho tìm kiếm, thăm dò và khai thác | D2: VPI | E2: Viện Dầu khí Việt Nam | F2: Chatbot hỏi đáp lĩnh dữ liệu chuyên môn (Well-log, E&P, Tạp chí Dầu khí,...)
A3: 3 | B3: =INDEX('Bài toán chuẩn'!$D:$D,MATCH(A3,'Bài toán chuẩn'!$A:$A,0)) -> Hiệu chỉnh và chuẩn hóa dữ liệu giếng khoan | C3: =INDEX('Bài toán chuẩn'!$B:$B,MATCH(A3,'Bài toán chuẩn'!$A:$A,0)) -> 1. AI cho tìm kiếm, thăm dò và khai thác | D3: VPI | E3: Viện Dầu khí Việt Nam | F3: Dự báo missing log
A4: 5 | B4: =INDEX('Bài toán chuẩn'!$D:$D,MATCH(A4,'Bài toán chuẩn'!$A:$A,0)) -> Phân tích, đánh giá và tổng hợp kết quả giếng khoan | C4: =INDEX('Bài toán chuẩn'!$B:$B,MATCH(A4,'Bài toán chuẩn'!$A:$A,0)) -> 1. AI cho tìm kiếm, thăm dò và khai thác | D4: PQPOC | E4: Chi nhánh Tập đoàn – Công ty Điều hành Dầu khí Phú Quốc | F4: Drilling AI
A5: 5 | B5: =INDEX('Bài toán chuẩn'!$D:$D,MATCH(A5,'Bài toán chuẩn'!$A:$A,0)) -> Phân tích, đánh giá và tổng hợp kết quả giếng khoan | C5: =INDEX('Bài toán chuẩn'!$B:$B,MATCH(A5,'Bài toán chuẩn'!$A:$A,0)) -> 1. AI cho tìm kiếm, thăm dò và khai thác | D5: PVEP | E5: Tổng công ty Thăm dò Khai thác Dầu khí | F5: Ứng dụng AI giám sát, phân tích và tư vấn tối ưu hóa thi công giếng khoan theo thời gian thực
A6: 6 | B6: =INDEX('Bài toán chuẩn'!$D:$D,MATCH(A6,'Bài toán chuẩn'!$A:$A,0)) -> Ứng dụng AI hỗ trợ minh giải cấu trúc địa chất | C6: =INDEX('Bài toán chuẩn'!$B:$B,MATCH(A6,'Bài toán chuẩn'!$A:$A,0)) -> 1. AI cho tìm kiếm, thăm dò và khai thác | D6: PVEP | E6: Tổng công ty Thăm dò Khai thác Dầu khí | F6: Ứng dụng Machine Learning trên Petrel hỗ trợ minh giải cấu trúc và xây dựng bản đồ địa chấn tại Lô B và Lô 01/10&02/10
A7: 7 | B7: =INDEX('Bài toán chuẩn'!$D:$D,MATCH(A7,'Bài toán chuẩn'!$A:$A,0)) -> AI hỗ trợ minh giải thuộc tính địa chấn đặc biệt | C7: =INDEX('Bài toán chuẩn'!$B:$B,MATCH(A7,'Bài toán chuẩn'!$A:$A,0)) -> 1. AI cho tìm kiếm, thăm dò và khai thác | D7: PVEP | E7: Tổng công ty Thăm dò Khai thác Dầu khí | F7: Ứng dụng AI/CNN trong nghịch đảo địa chấn, dự báo phân bố và thuộc tính đá chứa, đánh giá tiềm năng dầu khí phục vụ tối ưu giếng khoan và định hướng thăm dò tại các dự án của PVEP.
A8: 8 | B8: =INDEX('Bài toán chuẩn'!$D:$D,MATCH(A8,'Bài toán chuẩn'!$A:$A,0)) -> AI phân tích tổng hợp tài liệu địa chất, địa chấn để đánh giá tiềm năng dầu khí | C8: =INDEX('Bài toán chuẩn'!$B:$B,MATCH(A8,'Bài toán chuẩn'!$A:$A,0)) -> 1. AI cho tìm kiếm, thăm dò và khai thác | D8: VSP | E8: Liên doanh Việt – Nga Vietsovpetro | F8: ứng dụng AI/ML trong địa chất
A9: 10 | B9: =INDEX('Bài toán chuẩn'!$D:$D,MATCH(A9,'Bài toán chuẩn'!$A:$A,0)) -> Trợ lý AI tự động hóa quản lý doanh thu, chi phí, phân chia sản phẩm dầu/khí | C9: =INDEX('Bài toán chuẩn'!$B:$B,MATCH(A9,'Bài toán chuẩn'!$A:$A,0)) -> 1. AI cho tìm kiếm, thăm dò và khai thác | D9: PVEP | E9: Tổng công ty Thăm dò Khai thác Dầu khí | F9: Trợ lý AI tự động hóa quản lý doanh thu, chi phí, phân chia sản phẩm dầu/khí
A10: 11 | B10: =INDEX('Bài toán chuẩn'!$D:$D,MATCH(A10,'Bài toán chuẩn'!$A:$A,0)) -> Trợ lý AI quản trị, hỏi đáp, kiểm toán và rủi ro hợp đồng dầu khí | C10: =INDEX('Bài toán chuẩn'!$B:$B,MATCH(A10,'Bài toán chuẩn'!$A:$A,0)) -> 1. AI cho tìm kiếm, thăm dò và khai thác | D10: PVEP | E10: Tổng công ty Thăm dò Khai thác Dầu khí | F10: Trợ lý kiểm toán hợp đồng dầu khí
A11: 13 | B11: =INDEX('Bài toán chuẩn'!$D:$D,MATCH(A11,'Bài toán chuẩn'!$A:$A,0)) -> Ứng dụng AI đưa ra các phương án khai thác phù hợp dựa trên mô hình hiện hữu | C11: =INDEX('Bài toán chuẩn'!$B:$B,MATCH(A11,'Bài toán chuẩn'!$A:$A,0)) -> 1. AI cho tìm kiếm, thăm dò và khai thác | D11: PVEP | E11: Tổng công ty Thăm dò Khai thác Dầu khí | F11: AI hỗ trợ đánh giá và đề xuất giải pháp nâng cao hệ số thu hồi dầu
A12: 15 | B12: =INDEX('Bài toán chuẩn'!$D:$D,MATCH(A12,'Bài toán chuẩn'!$A:$A,0)) -> AI hỗ trợ tối ưu chế độ vận hành lò hơi thông qua điều chỉnh Oxy dư | C12: =INDEX('Bài toán chuẩn'!$B:$B,MATCH(A12,'Bài toán chuẩn'!$A:$A,0)) -> 2. AI cho vận hành, hiệu suất, độ tin cậy và toàn vẹn tài sản | D12: PVPGB | E12: Chi nhánh Phát điện Dầu khí | F12: AI hỗ trợ tính toán, đề xuất chế độ vận hành lò hơi của nhà máy nhiệt điện than thông qua điều chỉnh Oxy dư.
A13: 16 | B13: =INDEX('Bài toán chuẩn'!$D:$D,MATCH(A13,'Bài toán chuẩn'!$A:$A,0)) -> AI giám sát, tối ưu vận hành, năng lượng và phát thải nhà máy | C13: =INDEX('Bài toán chuẩn'!$B:$B,MATCH(A13,'Bài toán chuẩn'!$A:$A,0)) -> 2. AI cho vận hành, hiệu suất, độ tin cậy và toàn vẹn tài sản | D13: PVCFC | E13: Công ty Cổ phần Phân bón Dầu khí Cà Mau | F13: AI cho dự án nhà máy thông minh: hỗ trợ vận hành; bảo trì tuyên đoán; đánh giá công nghệ, thiết bị; tối ưu năng lượng;
... A71: 61 | B71: =INDEX('Bài toán chuẩn'!$D:$D,MATCH(A71,'Bài toán chuẩn'!$A:$A,0)) -> AI hỗ trợ R&D công nghệ, vật liệu, xúc tác và sản phẩm mới | C71: =INDEX('Bài toán chuẩn'!$B:$B,MATCH(A71,'Bài toán chuẩn'!$A:$A,0)) -> 7. AI cho nghiên cứu, đổi mới sáng tạo và sản phẩm, công nghệ | D71: PVU | E71: Trường Đại học Dầu khí Việt Nam | F71: Trợ lý AI hỗ trợ nghiên cứu khoa học, tìm kiếm và tổng hợp tài liệu
